<?xml version="1.0"?>
<robot name="rovi">
  <material name="Green">
    <color rgba="0 0.7 0 1"/>
  </material>
  <material name="White">
    <color rgba="0.7 0.7 0.7 1"/>
  </material>

  <link name="base_footprint"/>
  <link name="imu_link"/>

  <link name="base_link">
    <inertial>
      <origin xyz="0.00498197982182523 0.0000570233829969297 -0.0121008098068578" rpy="0 0 0"/>
      <mass value="0.486218814966626"/>
      <inertia ixx="0.00196277727666921" ixy="0.000000250447049446755" ixz="0.000140534767811098"
               iyy="0.00457256033711368" iyz="0.000000268618064993882" izz="0.00493927269870476"/>
    </inertial>
    <visual>
      <origin xyz="0 0 0" rpy="0 0 0"/>
      <geometry>
        <mesh filename="package://rovi_description/meshes/mecanum/base_link_X3.STL"/>
      </geometry>
      <material name="Green"/>
    </visual>
    <collision>
      <origin xyz="0 0 0" rpy="0 0 0"/>
      <geometry>
        <mesh filename="package://rovi_description/meshes/mecanum/base_link_X3.STL"/>
      </geometry>
    </collision>
  </link>

  <joint name="base_joint" type="fixed">
    <parent link="base_footprint"/>
    <child link="base_link"/>
    <origin xyz="0.0 0.0 0.0815" rpy="0 0 0"/>
  </joint>

  <joint name="base_imu" type="fixed">
    <parent link="base_link"/>
    <child link="imu_link"/>
    <origin xyz="-0.06 0.01 0.01" rpy="0 3.1415 1.5707"/>
  </joint>

  <link name="front_right_wheel">
    <inertial>
      <origin xyz="0.0000019051 -0.00000023183 -0.00064079" rpy="0 0 0"/>
      <mass value="0.051532"/>
      <inertia ixx="0.000014595" ixy="-0.00000000043975" ixz="0.0000000004415"
               iyy="0.000014594" iyz="-0.0000000017476" izz="0.000024264"/>
    </inertial>
    <visual>
      <origin xyz="0 0 0" rpy="0 0 0"/>
      <geometry>
        <mesh filename="package://rovi_description/meshes/mecanum/front_right_wheel_X3.STL"/>
      </geometry>
      <material name="White"/>
    </visual>
    <collision>
      <origin xyz="0 0 0" rpy="0 0 0"/>
      <geometry>
        <mesh filename="package://rovi_description/meshes/mecanum/front_right_wheel_X3.STL"/>
      </geometry>
    </collision>
  </link>

  <joint name="front_right_wheel_joint" type="continuous">
    <parent link="base_link"/>
    <child link="front_right_wheel"/>
    <origin xyz="0.08 -0.0845 -0.0389" rpy="-1.57079632679 0 3.14159265359"/>
    <axis xyz="0 0 1"/>
    <limit lower="-3.14159265359" upper="3.14159265359" effort="100" velocity="1"/>
  </joint>

  <link name="front_left_wheel">
    <inertial>
      <origin xyz="0.0000023728 -0.00000094228 0.00064068" rpy="0 0 0"/>
      <mass value="0.051543"/>
      <inertia ixx="0.000014597" ixy="-0.00000000047945" ixz="-0.00000000024786"
               iyy="0.000014598" iyz="0.0000000017972" izz="0.000024267"/>
    </inertial>
    <visual>
      <origin xyz="0 0 0" rpy="0 0 0"/>
      <geometry>
        <mesh filename="package://rovi_description/meshes/mecanum/front_left_wheel_X3.STL"/>
      </geometry>
      <material name="White"/>
    </visual>
    <collision>
      <origin xyz="0 0 0" rpy="0 0 0"/>
      <geometry>
        <mesh filename="package://rovi_description/meshes/mecanum/front_left_wheel_X3.STL"/>
      </geometry>
    </collision>
  </link>

  <joint name="front_left_wheel_joint" type="continuous">
    <parent link="base_link"/>
    <child link="front_left_wheel"/>
    <origin xyz="0.08 0.084492 -0.0389" rpy="1.57079632679 0 0"/>
    <axis xyz="0 0 1"/>
    <limit lower="-3.14159265359" upper="3.14159265359" effort="100" velocity="1"/>
  </joint>

  <link name="back_right_wheel">
    <inertial>
      <origin xyz="-0.00000175924169923403 0.00000128388821071107 -0.000590549296238266" rpy="0 0 0"/>
      <mass value="0.051540174053366"/>
      <inertia ixx="0.0000145974152250002" ixy="0.000000000194850559178397" ixz="-0.00000000161846387282284"
               iyy="0.000014596501955693" iyz="-0.000000000627904057423818" izz="0.0000242663091380451"/>
    </inertial>
    <visual>
      <origin xyz="0 0 0" rpy="0 0 0"/>
      <geometry>
        <mesh filename="package://rovi_description/meshes/mecanum/back_right_wheel_X3.STL"/>
      </geometry>
      <material name="White"/>
    </visual>
    <collision>
      <origin xyz="0 0 0" rpy="0 0 0"/>
      <geometry>
        <mesh filename="package://rovi_description/meshes/mecanum/back_right_wheel_X3.STL"/>
      </geometry>
    </collision>
  </link>

  <joint name="back_right_joint" type="continuous">
    <parent link="base_link"/>
    <child link="back_right_wheel"/>
    <origin xyz="-0.08 -0.0845 -0.03946" rpy="-1.57079632679 0 3.14159265359"/>
    <axis xyz="0 0 1"/>
    <limit lower="-3.14159265359" upper="3.14159265359" effort="100" velocity="1"/>
  </joint>

  <link name="back_left_wheel">
    <inertial>
      <origin xyz="-0.000000401213085227115 0.00000204910264598596 0.000590775697051377" rpy="0 0 0"/>
      <mass value="0.0515309299357028"/>
      <inertia ixx="0.0000145942986129926" ixy="-0.000000000319787215398093" ixz="0.00000000174943062058915"
               iyy="0.0000145948727598913" iyz="0.000000000161769812110049" izz="0.000024263683888153"/>
    </inertial>
    <visual>
      <origin xyz="0 0 0" rpy="0 0 0"/>
      <geometry>
        <mesh filename="package://rovi_description/meshes/mecanum/back_left_wheel_X3.STL"/>
      </geometry>
      <material name="White"/>
    </visual>
    <collision>
      <origin xyz="0 0 0" rpy="0 0 0"/>
      <geometry>
        <mesh filename="package://rovi_description/meshes/mecanum/back_left_wheel_X3.STL"/>
      </geometry>
    </collision>
  </link>

  <joint name="back_left_joint" type="continuous">
    <parent link="base_link"/>
    <child link="back_left_wheel"/>
    <origin xyz="-0.08 0.084492 -0.03954" rpy="1.57079632679 0 0"/>
    <axis xyz="0 0 1"/>
    <limit lower="-3.14159265359" upper="3.14159265359" effort="100" velocity="1"/>
  </joint>

  <link name="laser_link">
    <visual>
      <origin xyz="0 0 0" rpy="0 0 0"/>
      <geometry>
        <mesh filename="package://rovi_description/meshes/sensor/laser_link.STL"/>
      </geometry>
      <material name="White"/>
    </visual>
    <collision>
      <origin xyz="0 0 0" rpy="0 0 0"/>
      <geometry>
        <mesh filename="package://rovi_description/meshes/sensor/laser_link.STL"/>
      </geometry>
    </collision>
  </link>

  <joint name="laser_joint" type="fixed">
    <parent link="base_link"/>
    <child link="laser_link"/>
    <origin xyz="0 0 0.15" rpy="0 0 0"/>
  </joint>
</robot>
